<!DOCTYPE html>
<html lang="en">
<head>
    <meta charset="UTF-8">
    <meta name="viewport" content="width=device-width, initial-scale=1.0">
    <title>Document</title>
</head>
<body>
    <script>
        // const p1 = new Promise((resolve, reject) => {

        // })
        // console.log('p1', p1)

        // const p2 = new Promise((resolve, reject) => {
        //     setTimeout(() => {
        //         resolve()
        //     })
        // })
        // console.log('p2', p2)
        // setTimeout(() => {console.log('p2-setTimeout', p2)})

        const p3 = new Promise((resolve, reject) => {
            setTimeout(() => {
                reject()
            })
        })
        console.log('p3', p3)
        setTimeout(() => {console.log('p3-setTimeout', p3)})

        // const p4 = Promise.resolve(100)
        // console.log('p4', p4)

        // const p5 = Promise.reject('err')
        // console.log('p5', p5)

        // then 正常返回 resolved（fulfilled），里面有报错则返回 rejected
        // const p1 = Promise.resolve().then(() => {
        //     return 100
        // })
        // console.log('p1', p1)
        // p1.then(() => {
        //     console.log('123')
        // })
        // const p2 = Promise.resolve().then(() => {
        //     throw new Error('error')
        // })
        // console.log('p2', p2)

        // p2.then(() => {
        //     console.log('456')
        // }).catch((err) => {
        //     console.log('error', err)
        // })

        // catch 正常返回 resolved（fulfilled），里面有报错则返回 rejected
        // const p3 = Promise.reject('my error').catch((err => {
        //     console.log('err', err)
        // }))
        // console.log('p3', p3)
        // p3.then(() => {
        //     console.log('then', 100)
        // })

        // const p4 = Promise.reject('my error').catch((err => {
        //     throw new Error('p4 error')
        // }))
        // console.log('p4', p4)
        // p4.then(() => {
        //     console.log(200)
        // }).catch((err) => {
        //     console.log('catch err', err)
        // }).then(() => {
        //     console.log(500)
        //     throw new Error('error1')
        // }).catch(() => {
        //     console.log(600)
        // })

        // const p1 = new Promise((resolve, reject) => {
        //     reject('我是操作失败状态')
        // })
        // console.log('p1', p1)
        // p1.then(res => {
        //     console.log('then 回调触发: ', res)
        // }).catch(err => {
        //     console.log('catch 回调触发: ',err)
        // }).finally(() => {
        //     console.log('finally 回调触发')
        // })

    </script>
</body>
</html>